<?xml version='1.0'?>

<robot name="myrobot" xmlns:xacro="http://www.ros.org/wiki/xacro">

  <xacro:property name="cameraSize" value="0.05"/>
  <xacro:property name="cameraMass" value="0.1"/>

  <xacro:include filename="$(find mybot_description)/urdf/mybot.gazebo" />
  <xacro:include filename="$(find mybot_description)/urdf/materials.xacro" />
  
    <link name="base_link">
        <inertial>
            <mass value="3"/>
            <origin xyz="0 0 0"/>
            <inertia ixx="0.0282916666667" ixy="0" ixz="0" iyy="0.0282916666667" iyz="0" izz="0.05625"/>
        </inertial>
        <visual>
            <origin rpy="0 0 0" xyz="0 0 0"/>
            <geometry>
            <cylinder length="0.20" radius="0.75"/>
            </geometry>
            <material name="white"/>
        </visual>
        <collision>
            <origin rpy="0 0 0 " xyz="0 0 0"/>
            <geometry>
            <cylinder length="0.05" radius="0.75"/>
            </geometry>
        </collision>
    </link>

    <link name="right_wheel">
        <visual>
			<origin rpy="1.57079632679 0 0" xyz="0 0 0"/>
            <geometry>
                <cylinder length="0.1" radius="0.2"/>
            </geometry>
			<material name="blue"/>
        </visual>
		<collision>
		  <origin rpy="1.57079632679 0 0 " xyz="0 0 0"/>
		  <geometry>
		    <cylinder length="0.1" radius="0.2"/>
		  </geometry>
		</collision>
		<inertial>
		  <mass value="1"/>
		  <inertia ixx="1.0" ixy="0.0" ixz="0.0" iyy="1.0" iyz="0.0" izz="1.0"/>
		</inertial>
    </link>

    <joint name="right_wheel_joint" type="continuous">
      <parent link="base_link"/>
      <child link="right_wheel"/>
      <origin rpy="0 0 0" xyz="0.0 0.75 0.0"/>
      <axis rpy="0  0" xyz="0 1 0"/>
      <limit effort="100" velocity="100"/>
      <joint_properties damping="0.0" friction="0.0"/>
    </joint>

    <transmission name="right_wheel_control">
  		<type>transmission_interface/SimpleTransmission</type>
  		<actuator name="right_wheel_motor">
			<mechanicalReduction>1</mechanicalReduction>
  		</actuator>
  		<joint name="right_wheel_joint">
			<hardwareInterface>hardware_interface/EffortJointInterface</hardwareInterface>
  		</joint>
	</transmission>

    <link name="left_wheel">
        <visual>
			<origin rpy="1.57079632679 0 0" xyz="0 0 0"/>
            <geometry>
                <cylinder length="0.1" radius="0.2"/>
            </geometry>
			<material name="blue"/>
        </visual>
		<collision>
		  <origin rpy="1.57079632679 0 0" xyz="0 0 0"/>
		  <geometry>
		    <cylinder length="0.1" radius="0.2"/>
		  </geometry>
		</collision>
		<inertial>
		  <mass value="1"/>
		  <inertia ixx="1.0" ixy="0.0" ixz="0.0" iyy="1.0" iyz="0.0" izz="1.0"/>
		</inertial>
    </link>

    <joint name="left_wheel_joint" type="continuous">
	    <parent link="base_link"/>
	    <child link="left_wheel"/>
	    <origin rpy="0 0 0" xyz="0.0 -0.75 0.0"/>
	    <axis rpy="0  0" xyz="0 1 0"/>
	    <limit effort="100" velocity="100"/>
	    <joint_properties damping="0.0" friction="0.0"/>
	</joint>

    <transmission name="left_wheel_control">
		<type>transmission_interface/SimpleTransmission</type>
		<actuator name="left_wheel_motor">
			<mechanicalReduction>1</mechanicalReduction>
		</actuator>
		<joint name="left_wheel_joint">
			<hardwareInterface>hardware_interface/EffortJointInterface</hardwareInterface>
		</joint>
	</transmission>
    <!-- ============================= SENSORS ========================================= -->
    <link name="hokuyo_link">
        <visual>
	<origin rpy="0 0 0" xyz="0 0 0"/>
            <geometry>
                <box size="0.1 0.1 0.1"/>
            </geometry>
	<material name="red"/>
        </visual>
    </link>

    <joint name="hokuyo_joint" type="fixed">
		<parent link="base_link"/>
		<child link="hokuyo_link"/>
		<origin xyz="0.75 0 0.0" rpy="0 0.0 0" />
	</joint>

    <!-- =============================MicrosoftKinect ========================================= -->
    <link name="kinect_link">
        <inertial>
	  <mass value="0.001"/>
	  <origin xyz="0 0 0"/>
	  <inertia ixx="0.0001" ixy="0.0" ixz="0.0"
		   iyy="0.0001" iyz="0.0"
		   izz="0.0001"/>
	</inertial>	
        <visual>
	    <origin rpy="0 0 0" xyz="0 0 0"/>
            <geometry>
                <box size="0.2 0.6 0.2"/>
            </geometry>
        </visual>
    </link>

    <joint name="kinect_joint" type="fixed">
		<parent link="base_link"/>
		<child link="kinect_link"/>
		<origin xyz="0.00 0 0.2" rpy="0 0 0" />
	</joint>

     <!-- ====================================Camera Plugin========================================== -->
     
     <link name="camera">
	    <collision>
	      <origin xyz="0 0 0" rpy="0 0 0"/>
	      <geometry>
		<box size="0.05 0.05 0.05"/>
	      </geometry>
	    </collision>

	    <visual>
	      <origin xyz="0 0 0" rpy="0 0 0"/>
	      <geometry>
		<box size="0.05 0.05 0.05"/>
	      </geometry>
	      <material name="red-1">
		<color rgba="0 1 0 1"/>
	      </material>
	    </visual>

	    <inertial>
	      <mass value="0.1" />
	      <origin xyz="0 0 0" rpy="0 0 0"/>
	      <box_inertia m="0.1" x="0.05" y="0.05" z="0.05" />
	      <inertia ixx="1e-6" ixy="0" ixz="0" iyy="1e-6" iyz="0" izz="1e-6" />
	    </inertial>
	</link>

    <joint name="camera_joint" type="fixed">
	    <axis xyz="0 1 0" />
	    <origin xyz=".75 0 0.15" rpy="0 0 0"/>
	    <parent link="base_link"/>
	    <child link="camera"/>
	</joint>

    <!-- ====================================CASTER WHEELS========================================== -->

    <link name="caster_wheel_back">
		<visual>
			<origin rpy="0 0 0" xyz="0 0 -0.1"/>
			<geometry>
                <sphere radius="0.1"/>
            </geometry>
		</visual>
		<collision>
			<origin rpy="0 0 0" xyz="0 0 -0.1"/>
			<geometry>
                <sphere radius="0.1"/>
            </geometry>
		</collision>
		<inertial>
			<origin xyz="0 0 0" />
			<mass value="1"/>
			<inertia ixx="1.0" ixy="0.0" ixz="0.0" iyy="1.0" iyz="0.0" izz="1.0"/>
		</inertial>
	</link>

	<joint name="base_to_caster_back" type="fixed">
		<parent link="base_link"/>
		<child link="caster_wheel_back"/>
		<origin rpy="0 0 0" xyz="-0.650 0 0" />
	</joint>

    <link name="caster_wheel_front">
		<visual>
			<origin rpy="0 0 0" xyz="0 0 -0.1"/>
			<geometry>
				<sphere radius="0.1"/>
			</geometry>
		</visual>
		<collision>
			<origin rpy="0 0 0" xyz="0 0 -0.1"/>
			<geometry>
				<sphere radius="0.1"/>
			</geometry>
		</collision>
		<inertial>
			<origin xyz="0 0 0" />
			<mass value="1"/>
			<inertia ixx="1.0" ixy="0.0" ixz="0.0" iyy="1.0" iyz="0.0" izz="1.0"/>
		</inertial>
	</link>

	<joint name="base_to_caster_front" type="fixed">
		<parent link="base_link"/>
		<child link="caster_wheel_front"/>
		<origin rpy="0 0 0" xyz="0.650 0 0" />
	</joint>

</robot>
